Workbook

Sheet Ma trận
A1: Mã | B1: Thành tựu (điều kiện đo được) | C1: Kỳ xét | D1: Nguồn dữ liệu | E1: Số cấp huy hiệu dùng | F1: 1 · Chuyên cần | G1: 2 · Bài về nhà | J1: 3 · Trên lớp | M1: 4 · Thi (MT) | P1: 5 · Thử thách | S1: 6 · Chinh phục dạng | V1: 7 · Rank | X1: 8 · Nhiệm vụ | Y1: 9 · Tập thể lớp | Z1: 10 · Bí ẩn & Kỷ niệm
F2: Không Nghỉ | G2: Đúng Hẹn | H2: Bài Đẹp | I2: Khá Lên | J2: Lên Tay | K2: Lên Bảng | L2: Vững Bước | M2: Dạn Dày | N2: Tốp Đầu | O2: Bứt Phá | P2: Bền Bỉ | Q2: Tuyệt Đối | R2: Lên Tầm | S2: Khai Phá | T2: Kho Dạng | U2: Lấp Lỗ | V2: Leo Rank | W2: Vượt Lên | X2: Về Đích | Y2: Lớp Vô Địch | Z2: Thám Tử Đề | AA2: Thần May Mắn | AB2: Lội Ngược Dòng | AC2: Chạm Đáy Bật Lên
F3: KN | G3: DH | H3: BD | I3: KL | J3: LT | K3: LB | L3: VB | M3: DD | N3: TD | O3: BP | P3: BB | Q3: TDO | R3: LTA | S3: KP | T3: KD | U3: LL | V3: LR | W3: VL | X3: VD | Y3: LVD | Z3: TTD | AA3: TMM | AB3: LND | AC3: CDBL
A4: 1 · Chuyên cần — thành tựu CHÍNH (điều kiện đơn của 1★–3★, ngưỡng cao của 4★–5★)
A5: KN-1 | B5: Chuỗi buổi có mặt liên tục ≥ 10 buổi | C5: trọn đời | D5: buoi_hoc_hs.diem_danh | E5: =COUNTA(F5:AC5) | F5: ★1
A6: KN-2 | B6: Chuỗi buổi có mặt liên tục ≥ 30 buổi | C6: trọn đời | D6: buoi_hoc_hs.diem_danh | E6: =COUNTA(F6:AC6) | F6: ★2
A7: KN-3 | B7: Chuỗi buổi có mặt liên tục ≥ 60 buổi | C7: trọn đời | D7: buoi_hoc_hs.diem_danh | E7: =COUNTA(F7:AC7) | F7: ★3
A8: KN-4 | B8: Chuỗi buổi có mặt liên tục ≥ 90 buổi | C8: trọn đời | D8: buoi_hoc_hs.diem_danh | E8: =COUNTA(F8:AC8) | F8: ★4
A9: KN-5 | B9: Chuỗi buổi có mặt liên tục ≥ 150 buổi | C9: trọn đời | D9: buoi_hoc_hs.diem_danh | E9: =COUNTA(F9:AC9) | F9: ★5
A10: 2 · Bài về nhà — thành tựu CHÍNH (điều kiện đơn của 1★–3★, ngưỡng cao của 4★–5★)
A11: DH-1 | B11: Chuỗi bài BTVN nộp đủ, đúng hạn ≥ 10 bài | C11: trọn đời | D11: btvn_ket_qua.trang_thai_nop | E11: =COUNTA(F11:AC11) | G11: ★1
A12: DH-2 | B12: Chuỗi bài BTVN nộp đủ, đúng hạn ≥ 30 bài | C12: trọn đời | D12: btvn_ket_qua.trang_thai_nop | E12: =COUNTA(F12:AC12) | G12: ★2
A13: DH-3 | B13: Chuỗi bài BTVN nộp đủ, đúng hạn ≥ 60 bài | C13: trọn đời | D13: btvn_ket_qua.trang_thai_nop | E13: =COUNTA(F13:AC13) | G13: ★3
A14: DH-4 | B14: Chuỗi bài BTVN nộp đủ, đúng hạn ≥ 90 bài | C14: trọn đời | D14: btvn_ket_qua.trang_thai_nop | E14: =COUNTA(F14:AC14) | G14: ★4
A15: DH-5 | B15: Chuỗi bài BTVN nộp đủ, đúng hạn ≥ 150 bài | C15: trọn đời | D15: btvn_ket_qua.trang_thai_nop | E15: =COUNTA(F15:AC15) | G15: ★5
A16: BD-1 | B16: Số bài BTVN đúng ≥ 90% ≥ 5 bài | C16: trọn đời | D16: btvn_ket_qua.ti_le_dung | E16: =COUNTA(F16:AC16) | H16: ★1
A17: BD-2 | B17: Số bài BTVN đúng ≥ 90% ≥ 20 bài | C17: trọn đời | D17: btvn_ket_qua.ti_le_dung | E17: =COUNTA(F17:AC17) | H17: ★2
A18: BD-3 | B18: Số bài BTVN đúng ≥ 90% ≥ 50 bài | C18: trọn đời | D18: btvn_ket_qua.ti_le_dung | E18: =COUNTA(F18:AC18) | H18: ★3
A19: BD-4 | B19: Số bài BTVN đúng ≥ 90% ≥ 75 bài | C19: trọn đời | D19: btvn_ket_qua.ti_le_dung | E19: =COUNTA(F19:AC19) | H19: ★4
A20: BD-5 | B20: Số bài BTVN đúng ≥ 90% ≥ 110 bài | C20: trọn đời | D20: btvn_ket_qua.ti_le_dung | E20: =COUNTA(F20:AC20) | H20: ★5
A21: KL-1 | B21: Số tháng tỉ lệ đúng BTVN tăng (hoặc giữ ≥ 90%) ≥ 1 tháng | C21: trọn đời | D21: btvn_ket_qua.ti_le_dung | E21: =COUNTA(F21:AC21) | I21: ★1
A22: KL-2 | B22: Số tháng tỉ lệ đúng BTVN tăng (hoặc giữ ≥ 90%) ≥ 3 tháng | C22: trọn đời | D22: btvn_ket_qua.ti_le_dung | E22: =COUNTA(F22:AC22) | I22: ★2
A23: KL-3 | B23: Số tháng tỉ lệ đúng BTVN tăng (hoặc giữ ≥ 90%) ≥ 6 tháng | C23: trọn đời | D23: btvn_ket_qua.ti_le_dung | E23: =COUNTA(F23:AC23) | I23: ★3
A24: KL-4 | B24: Số tháng tỉ lệ đúng BTVN tăng (hoặc giữ ≥ 90%) ≥ 8 tháng | C24: trọn đời | D24: btvn_ket_qua.ti_le_dung | E24: =COUNTA(F24:AC24) | I24: ★4
A25: KL-5 | B25: Số tháng tỉ lệ đúng BTVN tăng (hoặc giữ ≥ 90%) ≥ 10 tháng | C25: trọn đời | D25: btvn_ket_qua.ti_le_dung | E25: =COUNTA(F25:AC25) | I25: ★5
A26: 3 · Trên lớp — thành tựu CHÍNH (điều kiện đơn của 1★–3★, ngưỡng cao của 4★–5★)
A27: LT-1 | B27: Số bài ET đúng ≥ 80% ≥ 3 bài | C27: trọn đời | D27: gami_grades (phase et) | E27: =COUNTA(F27:AC27) | J27: ★1
A28: LT-2 | B28: Số bài ET đúng ≥ 80% ≥ 15 bài | C28: trọn đời | D28: gami_grades (phase et) | E28: =COUNTA(F28:AC28) | J28: ★2
A29: LT-3 | B29: Số bài ET đúng ≥ 80% ≥ 40 bài | C29: trọn đời | D29: gami_grades (phase et) | E29: =COUNTA(F29:AC29) | J29: ★3
A30: LT-4 | B30: Số bài ET đúng ≥ 80% ≥ 60 bài | C30: trọn đời | D30: gami_grades (phase et) | E30: =COUNTA(F30:AC30) | J30: ★4
A31: LT-5 | B31: Số bài ET đúng ≥ 80% ≥ 90 bài | C31: trọn đời | D31: gami_grades (phase et) | E31: =COUNTA(F31:AC31) | J31: ★5
A32: LB-1 | B32: Số lần vào Nhất / Nhì / Giải 3 xếp hạng buổi ≥ 3 lần | C32: trọn đời | D32: buoi_giai | E32: =COUNTA(F32:AC32) | K32: ★1
A33: LB-2 | B33: Số lần vào Nhất / Nhì / Giải 3 xếp hạng buổi ≥ 15 lần | C33: trọn đời | D33: buoi_giai | E33: =COUNTA(F33:AC33) | K33: ★2
A34: LB-3 | B34: Số lần vào Nhất / Nhì / Giải 3 xếp hạng buổi ≥ 40 lần | C34: trọn đời | D34: buoi_giai | E34: =COUNTA(F34:AC34) | K34: ★3
A35: LB-4 | B35: Số lần vào Nhất / Nhì / Giải 3 xếp hạng buổi ≥ 60 lần | C35: trọn đời | D35: buoi_giai | E35: =COUNTA(F35:AC35) | K35: ★4
A36: LB-5 | B36: Số lần vào Nhất / Nhì / Giải 3 xếp hạng buổi ≥ 90 lần | C36: trọn đời | D36: buoi_giai | E36: =COUNTA(F36:AC36) | K36: ★5
A37: VB-1 | B37: Số tháng ET tốt hơn tháng trước (hoặc giữ ≥ 90%) ≥ 1 tháng | C37: trọn đời | D37: gami_grades (phase et) | E37: =COUNTA(F37:AC37) | L37: ★1
A38: VB-2 | B38: Số tháng ET tốt hơn tháng trước (hoặc giữ ≥ 90%) ≥ 3 tháng | C38: trọn đời | D38: gami_grades (phase et) | E38: =COUNTA(F38:AC38) | L38: ★2
A39: VB-3 | B39: Số tháng ET tốt hơn tháng trước (hoặc giữ ≥ 90%) ≥ 6 tháng | C39: trọn đời | D39: gami_grades (phase et) | E39: =COUNTA(F39:AC39) | L39: ★3
A40: VB-4 | B40: Số tháng ET tốt hơn tháng trước (hoặc giữ ≥ 90%) ≥ 8 tháng | C40: trọn đời | D40: gami_grades (phase et) | E40: =COUNTA(F40:AC40) | L40: ★4
...

Sheet Huy hiệu
A1: Loại | B1: Huy hiệu | C1: Sao | D1: Điều kiện (mã thành tựu) | E1: Diễn giải | F1: Số điều kiện (đếm từ Ma trận) | G1: Bản cứng | H1: EXP thưởng
A2: 1 · Chuyên cần | B2: Không Nghỉ | C2: ★1 | D2: KN-1 | E2: Chuỗi buổi có mặt liên tục ≥ 10 buổi | F2: =COUNTIF('Ma trận'!F$5:F$141,C2) | G2: — | H2: 0
A3: 1 · Chuyên cần | B3: Không Nghỉ | C3: ★2 | D3: KN-2 | E3: Chuỗi buổi có mặt liên tục ≥ 30 buổi | F3: =COUNTIF('Ma trận'!F$5:F$141,C3) | G3: — | H3: 0
A4: 1 · Chuyên cần | B4: Không Nghỉ | C4: ★3 | D4: KN-3 | E4: Chuỗi buổi có mặt liên tục ≥ 60 buổi | F4: =COUNTIF('Ma trận'!F$5:F$141,C4) | G4: — | H4: 100
A5: 1 · Chuyên cần | B5: Không Nghỉ | C5: ★4 | D5: KN-4 + A2·1T | E5: Chuỗi buổi có mặt liên tục ≥ 90 buổi · VÀ trong 1 tháng: Nộp đủ, đúng hạn mọi BTVN | F5: =COUNTIF('Ma trận'!F$5:F$141,C5) | G5: Có (GV trao) | H5: 200
A6: 1 · Chuyên cần | B6: Không Nghỉ | C6: ★5 | D6: KN-5 + A2·3T + A6·3T | E6: Chuỗi buổi có mặt liên tục ≥ 150 buổi · VÀ 3 tháng liên tiếp: Nộp đủ, đúng hạn mọi BTVN · Pass Thử thách ≥ 15 ngày | F6: =COUNTIF('Ma trận'!F$5:F$141,C6) | G6: Có (GV trao) | H6: 300
A7: 2 · Bài về nhà | B7: Đúng Hẹn | C7: ★1 | D7: DH-1 | E7: Chuỗi bài BTVN nộp đủ, đúng hạn ≥ 10 bài | F7: =COUNTIF('Ma trận'!G$5:G$141,C7) | G7: — | H7: 0
A8: 2 · Bài về nhà | B8: Đúng Hẹn | C8: ★2 | D8: DH-2 | E8: Chuỗi bài BTVN nộp đủ, đúng hạn ≥ 30 bài | F8: =COUNTIF('Ma trận'!G$5:G$141,C8) | G8: — | H8: 0
A9: 2 · Bài về nhà | B9: Đúng Hẹn | C9: ★3 | D9: DH-3 | E9: Chuỗi bài BTVN nộp đủ, đúng hạn ≥ 60 bài | F9: =COUNTIF('Ma trận'!G$5:G$141,C9) | G9: — | H9: 100
A10: 2 · Bài về nhà | B10: Đúng Hẹn | C10: ★4 | D10: DH-4 + A1·1T | E10: Chuỗi bài BTVN nộp đủ, đúng hạn ≥ 90 bài · VÀ trong 1 tháng: Đi học đủ mọi buổi (vắng thì đã học bù) | F10: =COUNTIF('Ma trận'!G$5:G$141,C10) | G10: Có (GV trao) | H10: 200
A11: 2 · Bài về nhà | B11: Đúng Hẹn | C11: ★5 | D11: DH-5 + A1·3T + A4·3T | E11: Chuỗi bài BTVN nộp đủ, đúng hạn ≥ 150 bài · VÀ 3 tháng liên tiếp: Đi học đủ mọi buổi (vắng thì đã học bù) · Tự luyện ≥ 200 câu đúng | F11: =COUNTIF('Ma trận'!G$5:G$141,C11) | G11: Có (GV trao) | H11: 300
A12: 2 · Bài về nhà | B12: Bài Đẹp | C12: ★1 | D12: BD-1 | E12: Số bài BTVN đúng ≥ 90% ≥ 5 bài | F12: =COUNTIF('Ma trận'!H$5:H$141,C12) | G12: — | H12: 0
A13: 2 · Bài về nhà | B13: Bài Đẹp | C13: ★2 | D13: BD-2 | E13: Số bài BTVN đúng ≥ 90% ≥ 20 bài | F13: =COUNTIF('Ma trận'!H$5:H$141,C13) | G13: — | H13: 0
A14: 2 · Bài về nhà | B14: Bài Đẹp | C14: ★3 | D14: BD-3 | E14: Số bài BTVN đúng ≥ 90% ≥ 50 bài | F14: =COUNTIF('Ma trận'!H$5:H$141,C14) | G14: — | H14: 100
A15: 2 · Bài về nhà | B15: Bài Đẹp | C15: ★4 | D15: BD-4 + B1·1T | E15: Số bài BTVN đúng ≥ 90% ≥ 75 bài · VÀ trong 1 tháng: ET đúng ≥ 80% ở ≥ 3/4 số bài ET | F15: =COUNTIF('Ma trận'!H$5:H$141,C15) | G15: Có (GV trao) | H15: 200
A16: 2 · Bài về nhà | B16: Bài Đẹp | C16: ★5 | D16: BD-5 + A2·3T + B1·3T + B2·3T | E16: Số bài BTVN đúng ≥ 90% ≥ 110 bài · VÀ 3 tháng liên tiếp: Nộp đủ, đúng hạn mọi BTVN · ET đúng ≥ 80% ở ≥ 3/4 số bài ET · MT top 30% khối | F16: =COUNTIF('Ma trận'!H$5:H$141,C16) | G16: Có (GV trao) | H16: 300
A17: 2 · Bài về nhà | B17: Khá Lên | C17: ★1 | D17: KL-1 | E17: Số tháng tỉ lệ đúng BTVN tăng (hoặc giữ ≥ 90%) ≥ 1 tháng | F17: =COUNTIF('Ma trận'!I$5:I$141,C17) | G17: — | H17: 0
A18: 2 · Bài về nhà | B18: Khá Lên | C18: ★2 | D18: KL-2 | E18: Số tháng tỉ lệ đúng BTVN tăng (hoặc giữ ≥ 90%) ≥ 3 tháng | F18: =COUNTIF('Ma trận'!I$5:I$141,C18) | G18: — | H18: 0
A19: 2 · Bài về nhà | B19: Khá Lên | C19: ★3 | D19: KL-3 | E19: Số tháng tỉ lệ đúng BTVN tăng (hoặc giữ ≥ 90%) ≥ 6 tháng | F19: =COUNTIF('Ma trận'!I$5:I$141,C19) | G19: — | H19: 100
A20: 2 · Bài về nhà | B20: Khá Lên | C20: ★4 | D20: KL-4 + A2·1T | E20: Số tháng tỉ lệ đúng BTVN tăng (hoặc giữ ≥ 90%) ≥ 8 tháng · VÀ trong 1 tháng: Nộp đủ, đúng hạn mọi BTVN | F20: =COUNTIF('Ma trận'!I$5:I$141,C20) | G20: Có (GV trao) | H20: 200
A21: 2 · Bài về nhà | B21: Khá Lên | C21: ★5 | D21: KL-5 + A2·3T + C1·3T | E21: Số tháng tỉ lệ đúng BTVN tăng (hoặc giữ ≥ 90%) ≥ 10 tháng · VÀ 3 tháng liên tiếp: Nộp đủ, đúng hạn mọi BTVN · Hạng MT tăng so với tháng trước (hoặc giữ top 10%) | F21: =COUNTIF('Ma trận'!I$5:I$141,C21) | G21: Có (GV trao) | H21: 300
A22: 3 · Trên lớp | B22: Lên Tay | C22: ★1 | D22: LT-1 | E22: Số bài ET đúng ≥ 80% ≥ 3 bài | F22: =COUNTIF('Ma trận'!J$5:J$141,C22) | G22: — | H22: 0
A23: 3 · Trên lớp | B23: Lên Tay | C23: ★2 | D23: LT-2 | E23: Số bài ET đúng ≥ 80% ≥ 15 bài | F23: =COUNTIF('Ma trận'!J$5:J$141,C23) | G23: — | H23: 0
A24: 3 · Trên lớp | B24: Lên Tay | C24: ★3 | D24: LT-3 | E24: Số bài ET đúng ≥ 80% ≥ 40 bài | F24: =COUNTIF('Ma trận'!J$5:J$141,C24) | G24: — | H24: 100
A25: 3 · Trên lớp | B25: Lên Tay | C25: ★4 | D25: LT-4 + B4·1T | E25: Số bài ET đúng ≥ 80% ≥ 60 bài · VÀ trong 1 tháng: BTVN đúng trung bình ≥ 85% | F25: =COUNTIF('Ma trận'!J$5:J$141,C25) | G25: Có (GV trao) | H25: 200
A26: 3 · Trên lớp | B26: Lên Tay | C26: ★5 | D26: LT-5 + B3·3T + B5·3T | E26: Số bài ET đúng ≥ 80% ≥ 90 bài · VÀ 3 tháng liên tiếp: MT top 10% khối · BTVN đúng trung bình ≥ 90% | F26: =COUNTIF('Ma trận'!J$5:J$141,C26) | G26: Có (GV trao) | H26: 300
A27: 3 · Trên lớp | B27: Lên Bảng | C27: ★1 | D27: LB-1 | E27: Số lần vào Nhất / Nhì / Giải 3 xếp hạng buổi ≥ 3 lần | F27: =COUNTIF('Ma trận'!K$5:K$141,C27) | G27: — | H27: 0
A28: 3 · Trên lớp | B28: Lên Bảng | C28: ★2 | D28: LB-2 | E28: Số lần vào Nhất / Nhì / Giải 3 xếp hạng buổi ≥ 15 lần | F28: =COUNTIF('Ma trận'!K$5:K$141,C28) | G28: — | H28: 0
A29: 3 · Trên lớp | B29: Lên Bảng | C29: ★3 | D29: LB-3 | E29: Số lần vào Nhất / Nhì / Giải 3 xếp hạng buổi ≥ 40 lần | F29: =COUNTIF('Ma trận'!K$5:K$141,C29) | G29: — | H29: 100
A30: 3 · Trên lớp | B30: Lên Bảng | C30: ★4 | D30: LB-4 + B1·1T | E30: Số lần vào Nhất / Nhì / Giải 3 xếp hạng buổi ≥ 60 lần · VÀ trong 1 tháng: ET đúng ≥ 80% ở ≥ 3/4 số bài ET | F30: =COUNTIF('Ma trận'!K$5:K$141,C30) | G30: Có (GV trao) | H30: 200
A31: 3 · Trên lớp | B31: Lên Bảng | C31: ★5 | D31: LB-5 + A1·3T + B1·3T | E31: Số lần vào Nhất / Nhì / Giải 3 xếp hạng buổi ≥ 90 lần · VÀ 3 tháng liên tiếp: Đi học đủ mọi buổi (vắng thì đã học bù) · ET đúng ≥ 80% ở ≥ 3/4 số bài ET | F31: =COUNTIF('Ma trận'!K$5:K$141,C31) | G31: Có (GV trao) | H31: 300
A32: 3 · Trên lớp | B32: Vững Bước | C32: ★1 | D32: VB-1 | E32: Số tháng ET tốt hơn tháng trước (hoặc giữ ≥ 90%) ≥ 1 tháng | F32: =COUNTIF('Ma trận'!L$5:L$141,C32) | G32: — | H32: 0
A33: 3 · Trên lớp | B33: Vững Bước | C33: ★2 | D33: VB-2 | E33: Số tháng ET tốt hơn tháng trước (hoặc giữ ≥ 90%) ≥ 3 tháng | F33: =COUNTIF('Ma trận'!L$5:L$141,C33) | G33: — | H33: 0
A34: 3 · Trên lớp | B34: Vững Bước | C34: ★3 | D34: VB-3 | E34: Số tháng ET tốt hơn tháng trước (hoặc giữ ≥ 90%) ≥ 6 tháng | F34: =COUNTIF('Ma trận'!L$5:L$141,C34) | G34: — | H34: 100
A35: 3 · Trên lớp | B35: Vững Bước | C35: ★4 | D35: VB-4 + C2·1T | E35: Số tháng ET tốt hơn tháng trước (hoặc giữ ≥ 90%) ≥ 8 tháng · VÀ trong 1 tháng: Tỉ lệ đúng BTVN tăng ≥ 5 điểm so với tháng trước (hoặc giữ ≥ 90%) | F35: =COUNTIF('Ma trận'!L$5:L$141,C35) | G35: Có (GV trao) | H35: 200
A36: 3 · Trên lớp | B36: Vững Bước | C36: ★5 | D36: VB-5 + C1·3T + C2·3T | E36: Số tháng ET tốt hơn tháng trước (hoặc giữ ≥ 90%) ≥ 10 tháng · VÀ 3 tháng liên tiếp: Hạng MT tăng so với tháng trước (hoặc giữ top 10%) · Tỉ lệ đúng BTVN tăng ≥ 5 điểm so với tháng trước (hoặc giữ ≥ 90%) | F36: =COUNTIF('Ma trận'!L$5:L$141,C36) | G36: Có (GV trao) | H36: 300
A37: 4 · Thi (MT) | B37: Dạn Dày | C37: ★1 | D37: DD-1 | E37: Số kỳ MT đã dự (kể cả thi lại) ≥ 1 kỳ | F37: =COUNTIF('Ma trận'!M$5:M$141,C37) | G37: — | H37: 0
A38: 4 · Thi (MT) | B38: Dạn Dày | C38: ★2 | D38: DD-2 | E38: Số kỳ MT đã dự (kể cả thi lại) ≥ 4 kỳ | F38: =COUNTIF('Ma trận'!M$5:M$141,C38) | G38: — | H38: 0
A39: 4 · Thi (MT) | B39: Dạn Dày | C39: ★3 | D39: DD-3 | E39: Số kỳ MT đã dự (kể cả thi lại) ≥ 8 kỳ | F39: =COUNTIF('Ma trận'!M$5:M$141,C39) | G39: — | H39: 100
A40: 4 · Thi (MT) | B40: Dạn Dày | C40: ★4 | D40: DD-4 + A1·1T + A2·1T | E40: Số kỳ MT đã dự (kể cả thi lại) ≥ 10 kỳ · VÀ trong 1 tháng: Đi học đủ mọi buổi (vắng thì đã học bù) · Nộp đủ, đúng hạn mọi BTVN | F40: =COUNTIF('Ma trận'!M$5:M$141,C40) | G40: Có (GV trao) | H40: 200
...

Sheet Ghi chú
A1: MA TRẬN THÀNH TỰU × HUY HIỆU — môn TOÁN · nháp 3 · CTO 28/09/2026
A3: Cách đọc
A4: • Hàng = THÀNH TỰU: 1 điều kiện đo được trên dữ liệu thật (chỉ số + ngưỡng + kỳ xét).
A5: • Cột = HUY HIỆU (10 loại, 24 huy hiệu). Ô ghi SAO nào của huy hiệu dùng thành tựu đó.
A6: • Một cấp sao đạt khi đạt TẤT CẢ thành tựu mang nhãn sao đó trong cột. Liên kết N–N: 1 thành tựu nuôi nhiều huy hiệu (cột E), 1 huy hiệu dùng nhiều thành tựu.
A7: • ★1–★3 = điều kiện đơn (bản mềm). ★4–★5 = nhiều điều kiện (bản mềm + bản cứng GV trao) — ô nền vàng chữ đỏ.
A9: Cách sửa
A10: • Đổi điều kiện của 1 cấp: gõ / xoá nhãn ★n trong ô của cột huy hiệu đó (sheet Huy hiệu tự đếm lại cột 'Số điều kiện').
A11: • Đổi ngưỡng: sửa chữ ở cột B của thành tựu tương ứng.
A12: • Ví dụ: muốn Không Nghỉ ★5 thêm điều kiện 'MT top 30%' ⇒ gõ ★5 vào ô hàng B2·3T (nếu chưa có hàng thì thêm hàng) × cột Không Nghỉ.
A14: Giả định chưa chốt
A15: • H7: ★4 = trong tháng vượt ngưỡng chính phải đạt đủ thành tựu phụ '·1T'. ★5 = các thành tựu phụ '·3T' đạt CÙNG 1 cửa sổ 3 tháng liên tiếp.
... A21: Nguồn: spec-thanh-tuu-nhiem-vu.md (A5) · de-xuat-huy-hieu.md · số đo DB chỉ đọc 28/09/2026.
